2024-06-25 16:03:53,053 - __main__ - ERROR - Uncaught exception:
   File "C:\Users\Raphael Girault\Desktop\DLS_git\utils\acquisition\interface_thread.py", line 50, in setup
    self.fpga_serial_ascii=FPGA_interface.FPGA_serial_ASCII()
                           ^^^^^^^^^^^^^^^^^^^^^^^^^^^^^^^^^^
  File "C:\Users\Raphael Girault\Desktop\DLS_git\utils\FPGA_interface.py", line 26, in __init__
    self.FPGA_ascii = serial.Serial(self.FPGA_ascii_port, baud_rate=self.baudrate,parity=self.parity, bytesize=self.bytesize)
                                    ^^^^^^^^^^^^^^^^^^^^

AttributeError: 'FPGA_serial_ASCII' object has no attribute 'FPGA_ascii_port'
  --------------------- 
2024-06-25 16:03:57,498 - __main__ - ERROR - Uncaught exception:
   File "C:\Users\Raphael Girault\Desktop\DLS_git\utils\GUI\calibration_ctl.py", line 40, in start_calibration
    self.new_winsetup()
    ^^^^^^^^^^^^^^^^^

AttributeError: 'Calibration' object has no attribute 'new_winsetup'
  --------------------- 
